running 2 tests
          test example::test_success ... ok
          test example::test_failure ... FAILED

          failures:

          ---- example::test_failure stdout ----
          thread 'example::test_failure' panicked at 'assertion failed'

          test result: FAILED. 1 passed; 1 failed; 0 ignored; 0 measured; 0 filtered out; finished in 0.01s
